/home/emanuel/firebase_mqtt.py:53: DeprecationWarning: Callback API version 1 is deprecated, update to latest version
  client = mqtt.Client(client_id="firebase", protocol=mqtt.MQTTv5)
/home/emanuel/firebase_mqtt.py:74: DeprecationWarning: Callback API version 1 is deprecated, update to latest version
/home/emanuel/firebase_mqtt.py:74: DeprecationWarning: Callback API version 1 is deprecated, update to latest version
/home/emanuel/firebase_mqtt.py:74: DeprecationWarning: Callback API version 1 is deprecated, update to latest version
Exception in thread Thread-1 (start_firebase_watch):
Traceback (most recent call last):
  File "/home/emanuel/ojos-env/lib/python3.11/site-packages/urllib3/connection.py", line 198, in _new_conn
    sock = connection.create_connection(
           ^^^^^^^^^^^^^^^^^^^^^^^^^^^^^
  File "/home/emanuel/ojos-env/lib/python3.11/site-packages/urllib3/util/connection.py", line 60, in create_connection
    for res in socket.getaddrinfo(host, port, family, socket.SOCK_STREAM):
               ^^^^^^^^^^^^^^^^^^^^^^^^^^^^^^^^^^^^^^^^^^^^^^^^^^^^^^^^^^
  File "/usr/lib/python3.11/socket.py", line 962, in getaddrinfo
    for res in _socket.getaddrinfo(host, port, family, type, proto, flags):
               ^^^^^^^^^^^^^^^^^^^^^^^^^^^^^^^^^^^^^^^^^^^^^^^^^^^^^^^^^^^
socket.gaierror: [Errno -3] Temporary failure in name resolution

The above exception was the direct cause of the following exception:

Traceback (most recent call last):
  File "/home/emanuel/ojos-env/lib/python3.11/site-packages/urllib3/connectionpool.py", line 787, in urlopen
    response = self._make_request(
               ^^^^^^^^^^^^^^^^^^^
  File "/home/emanuel/ojos-env/lib/python3.11/site-packages/urllib3/connectionpool.py", line 488, in _make_request
    raise new_e
  File "/home/emanuel/ojos-env/lib/python3.11/site-packages/urllib3/connectionpool.py", line 464, in _make_request
    self._validate_conn(conn)
  File "/home/emanuel/ojos-env/lib/python3.11/site-packages/urllib3/connectionpool.py", line 1093, in _validate_conn
    conn.connect()
  File "/home/emanuel/ojos-env/lib/python3.11/site-packages/urllib3/connection.py", line 753, in connect
    self.sock = sock = self._new_conn()
                       ^^^^^^^^^^^^^^^^
  File "/home/emanuel/ojos-env/lib/python3.11/site-packages/urllib3/connection.py", line 205, in _new_conn
    raise NameResolutionError(self.host, self, e) from e
urllib3.exceptions.NameResolutionError: <urllib3.connection.HTTPSConnection object at 0x7fff3d3da5d0>: Failed to resolve 'oauth2.googleapis.com' ([Errno -3] Temporary failure in name resolution)

The above exception was the direct cause of the following exception:

Traceback (most recent call last):
  File "/home/emanuel/ojos-env/lib/python3.11/site-packages/requests/adapters.py", line 644, in send
    resp = conn.urlopen(
           ^^^^^^^^^^^^^
  File "/home/emanuel/ojos-env/lib/python3.11/site-packages/urllib3/connectionpool.py", line 871, in urlopen
    return self.urlopen(
           ^^^^^^^^^^^^^
  File "/home/emanuel/ojos-env/lib/python3.11/site-packages/urllib3/connectionpool.py", line 871, in urlopen
    return self.urlopen(
           ^^^^^^^^^^^^^
  File "/home/emanuel/ojos-env/lib/python3.11/site-packages/urllib3/connectionpool.py", line 871, in urlopen
    return self.urlopen(
           ^^^^^^^^^^^^^
  File "/home/emanuel/ojos-env/lib/python3.11/site-packages/urllib3/connectionpool.py", line 841, in urlopen
    retries = retries.increment(
              ^^^^^^^^^^^^^^^^^^
  File "/home/emanuel/ojos-env/lib/python3.11/site-packages/urllib3/util/retry.py", line 519, in increment
    raise MaxRetryError(_pool, url, reason) from reason  # type: ignore[arg-type]
    ^^^^^^^^^^^^^^^^^^^^^^^^^^^^^^^^^^^^^^^^^^^^^^^^^^^
urllib3.exceptions.MaxRetryError: HTTPSConnectionPool(host='oauth2.googleapis.com', port=443): Max retries exceeded with url: /token (Caused by NameResolutionError("<urllib3.connection.HTTPSConnection object at 0x7fff3d3da5d0>: Failed to resolve 'oauth2.googleapis.com' ([Errno -3] Temporary failure in name resolution)"))

During handling of the above exception, another exception occurred:

Traceback (most recent call last):
  File "/home/emanuel/ojos-env/lib/python3.11/site-packages/google/auth/transport/requests.py", line 187, in __call__
    response = self.session.request(
               ^^^^^^^^^^^^^^^^^^^^^
  File "/home/emanuel/ojos-env/lib/python3.11/site-packages/requests/sessions.py", line 589, in request
    resp = self.send(prep, **send_kwargs)
           ^^^^^^^^^^^^^^^^^^^^^^^^^^^^^^
  File "/home/emanuel/ojos-env/lib/python3.11/site-packages/requests/sessions.py", line 703, in send
    r = adapter.send(request, **kwargs)
        ^^^^^^^^^^^^^^^^^^^^^^^^^^^^^^^
  File "/home/emanuel/ojos-env/lib/python3.11/site-packages/requests/adapters.py", line 677, in send
    raise ConnectionError(e, request=request)
requests.exceptions.ConnectionError: HTTPSConnectionPool(host='oauth2.googleapis.com', port=443): Max retries exceeded with url: /token (Caused by NameResolutionError("<urllib3.connection.HTTPSConnection object at 0x7fff3d3da5d0>: Failed to resolve 'oauth2.googleapis.com' ([Errno -3] Temporary failure in name resolution)"))

The above exception was the direct cause of the following exception:

Traceback (most recent call last):
  File "/usr/lib/python3.11/threading.py", line 1038, in _bootstrap_inner
    self.run()
  File "/usr/lib/python3.11/threading.py", line 975, in run
    self._target(*self._args, **self._kwargs)
  File "/home/emanuel/firebase_mqtt.py", line 98, in start_firebase_watch
  File "/home/emanuel/ojos-env/lib/python3.11/site-packages/firebase_admin/db.py", line 374, in listen
    return self._listen_with_session(callback)
           ^^^^^^^^^^^^^^^^^^^^^^^^^^^^^^^^^^^
  File "/home/emanuel/ojos-env/lib/python3.11/site-packages/firebase_admin/db.py", line 469, in _listen_with_session
    sse = _sseclient.SSEClient(url, session, **{"params": self._client.params})
          ^^^^^^^^^^^^^^^^^^^^^^^^^^^^^^^^^^^^^^^^^^^^^^^^^^^^^^^^^^^^^^^^^^^^^
  File "/home/emanuel/ojos-env/lib/python3.11/site-packages/firebase_admin/_sseclient.py", line 97, in __init__
    self._connect()
  File "/home/emanuel/ojos-env/lib/python3.11/site-packages/firebase_admin/_sseclient.py", line 110, in _connect
    self.resp = self.session.get(self.url, stream=True, **self.requests_kwargs)
                ^^^^^^^^^^^^^^^^^^^^^^^^^^^^^^^^^^^^^^^^^^^^^^^^^^^^^^^^^^^^^^^
  File "/home/emanuel/ojos-env/lib/python3.11/site-packages/requests/sessions.py", line 602, in get
    return self.request("GET", url, **kwargs)
           ^^^^^^^^^^^^^^^^^^^^^^^^^^^^^^^^^^
  File "/home/emanuel/ojos-env/lib/python3.11/site-packages/google/auth/transport/requests.py", line 535, in request
    self.credentials.before_request(auth_request, method, url, request_headers)
  File "/home/emanuel/ojos-env/lib/python3.11/site-packages/google/auth/credentials.py", line 239, in before_request
    self._blocking_refresh(request)
  File "/home/emanuel/ojos-env/lib/python3.11/site-packages/google/auth/credentials.py", line 202, in _blocking_refresh
    self.refresh(request)
  File "/home/emanuel/ojos-env/lib/python3.11/site-packages/google/oauth2/service_account.py", line 448, in refresh
    access_token, expiry, _ = _client.jwt_grant(
                              ^^^^^^^^^^^^^^^^^^
  File "/home/emanuel/ojos-env/lib/python3.11/site-packages/google/oauth2/_client.py", line 299, in jwt_grant
    response_data = _token_endpoint_request(
                    ^^^^^^^^^^^^^^^^^^^^^^^^
  File "/home/emanuel/ojos-env/lib/python3.11/site-packages/google/oauth2/_client.py", line 259, in _token_endpoint_request
    response_status_ok, response_data, retryable_error = _token_endpoint_request_no_throw(
                                                         ^^^^^^^^^^^^^^^^^^^^^^^^^^^^^^^^^
  File "/home/emanuel/ojos-env/lib/python3.11/site-packages/google/oauth2/_client.py", line 192, in _token_endpoint_request_no_throw
    response = request(
               ^^^^^^^^
  File "/home/emanuel/ojos-env/lib/python3.11/site-packages/google/auth/transport/requests.py", line 194, in __call__
    raise new_exc from caught_exc
google.auth.exceptions.TransportError: HTTPSConnectionPool(host='oauth2.googleapis.com', port=443): Max retries exceeded with url: /token (Caused by NameResolutionError("<urllib3.connection.HTTPSConnection object at 0x7fff3d3da5d0>: Failed to resolve 'oauth2.googleapis.com' ([Errno -3] Temporary failure in name resolution)"))
/home/emanuel/firebase_mqtt.py:74: DeprecationWarning: Callback API version 1 is deprecated, update to latest version
Exception in thread Thread-1 (start_firebase_watch):
Traceback (most recent call last):
  File "/home/emanuel/ojos-env/lib/python3.11/site-packages/urllib3/connection.py", line 198, in _new_conn
    sock = connection.create_connection(
           ^^^^^^^^^^^^^^^^^^^^^^^^^^^^^
  File "/home/emanuel/ojos-env/lib/python3.11/site-packages/urllib3/util/connection.py", line 60, in create_connection
    for res in socket.getaddrinfo(host, port, family, socket.SOCK_STREAM):
               ^^^^^^^^^^^^^^^^^^^^^^^^^^^^^^^^^^^^^^^^^^^^^^^^^^^^^^^^^^
  File "/usr/lib/python3.11/socket.py", line 962, in getaddrinfo
    for res in _socket.getaddrinfo(host, port, family, type, proto, flags):
               ^^^^^^^^^^^^^^^^^^^^^^^^^^^^^^^^^^^^^^^^^^^^^^^^^^^^^^^^^^^
socket.gaierror: [Errno -3] Temporary failure in name resolution

The above exception was the direct cause of the following exception:

Traceback (most recent call last):
  File "/home/emanuel/ojos-env/lib/python3.11/site-packages/urllib3/connectionpool.py", line 787, in urlopen
    response = self._make_request(
               ^^^^^^^^^^^^^^^^^^^
  File "/home/emanuel/ojos-env/lib/python3.11/site-packages/urllib3/connectionpool.py", line 488, in _make_request
    raise new_e
  File "/home/emanuel/ojos-env/lib/python3.11/site-packages/urllib3/connectionpool.py", line 464, in _make_request
    self._validate_conn(conn)
  File "/home/emanuel/ojos-env/lib/python3.11/site-packages/urllib3/connectionpool.py", line 1093, in _validate_conn
    conn.connect()
  File "/home/emanuel/ojos-env/lib/python3.11/site-packages/urllib3/connection.py", line 753, in connect
    self.sock = sock = self._new_conn()
                       ^^^^^^^^^^^^^^^^
  File "/home/emanuel/ojos-env/lib/python3.11/site-packages/urllib3/connection.py", line 205, in _new_conn
    raise NameResolutionError(self.host, self, e) from e
urllib3.exceptions.NameResolutionError: <urllib3.connection.HTTPSConnection object at 0x7fff5403a710>: Failed to resolve 'oauth2.googleapis.com' ([Errno -3] Temporary failure in name resolution)

The above exception was the direct cause of the following exception:

Traceback (most recent call last):
  File "/home/emanuel/ojos-env/lib/python3.11/site-packages/requests/adapters.py", line 644, in send
    resp = conn.urlopen(
           ^^^^^^^^^^^^^
  File "/home/emanuel/ojos-env/lib/python3.11/site-packages/urllib3/connectionpool.py", line 871, in urlopen
    return self.urlopen(
           ^^^^^^^^^^^^^
  File "/home/emanuel/ojos-env/lib/python3.11/site-packages/urllib3/connectionpool.py", line 871, in urlopen
    return self.urlopen(
           ^^^^^^^^^^^^^
  File "/home/emanuel/ojos-env/lib/python3.11/site-packages/urllib3/connectionpool.py", line 871, in urlopen
    return self.urlopen(
           ^^^^^^^^^^^^^
  File "/home/emanuel/ojos-env/lib/python3.11/site-packages/urllib3/connectionpool.py", line 841, in urlopen
    retries = retries.increment(
              ^^^^^^^^^^^^^^^^^^
  File "/home/emanuel/ojos-env/lib/python3.11/site-packages/urllib3/util/retry.py", line 519, in increment
    raise MaxRetryError(_pool, url, reason) from reason  # type: ignore[arg-type]
    ^^^^^^^^^^^^^^^^^^^^^^^^^^^^^^^^^^^^^^^^^^^^^^^^^^^
urllib3.exceptions.MaxRetryError: HTTPSConnectionPool(host='oauth2.googleapis.com', port=443): Max retries exceeded with url: /token (Caused by NameResolutionError("<urllib3.connection.HTTPSConnection object at 0x7fff5403a710>: Failed to resolve 'oauth2.googleapis.com' ([Errno -3] Temporary failure in name resolution)"))

During handling of the above exception, another exception occurred:

Traceback (most recent call last):
  File "/home/emanuel/ojos-env/lib/python3.11/site-packages/google/auth/transport/requests.py", line 187, in __call__
    response = self.session.request(
               ^^^^^^^^^^^^^^^^^^^^^
  File "/home/emanuel/ojos-env/lib/python3.11/site-packages/requests/sessions.py", line 589, in request
    resp = self.send(prep, **send_kwargs)
           ^^^^^^^^^^^^^^^^^^^^^^^^^^^^^^
  File "/home/emanuel/ojos-env/lib/python3.11/site-packages/requests/sessions.py", line 703, in send
    r = adapter.send(request, **kwargs)
        ^^^^^^^^^^^^^^^^^^^^^^^^^^^^^^^
  File "/home/emanuel/ojos-env/lib/python3.11/site-packages/requests/adapters.py", line 677, in send
    raise ConnectionError(e, request=request)
requests.exceptions.ConnectionError: HTTPSConnectionPool(host='oauth2.googleapis.com', port=443): Max retries exceeded with url: /token (Caused by NameResolutionError("<urllib3.connection.HTTPSConnection object at 0x7fff5403a710>: Failed to resolve 'oauth2.googleapis.com' ([Errno -3] Temporary failure in name resolution)"))

The above exception was the direct cause of the following exception:

Traceback (most recent call last):
  File "/usr/lib/python3.11/threading.py", line 1038, in _bootstrap_inner
    self.run()
  File "/usr/lib/python3.11/threading.py", line 975, in run
    self._target(*self._args, **self._kwargs)
  File "/home/emanuel/firebase_mqtt.py", line 98, in start_firebase_watch
  File "/home/emanuel/ojos-env/lib/python3.11/site-packages/firebase_admin/db.py", line 374, in listen
    return self._listen_with_session(callback)
           ^^^^^^^^^^^^^^^^^^^^^^^^^^^^^^^^^^^
  File "/home/emanuel/ojos-env/lib/python3.11/site-packages/firebase_admin/db.py", line 469, in _listen_with_session
    sse = _sseclient.SSEClient(url, session, **{"params": self._client.params})
          ^^^^^^^^^^^^^^^^^^^^^^^^^^^^^^^^^^^^^^^^^^^^^^^^^^^^^^^^^^^^^^^^^^^^^
  File "/home/emanuel/ojos-env/lib/python3.11/site-packages/firebase_admin/_sseclient.py", line 97, in __init__
    self._connect()
  File "/home/emanuel/ojos-env/lib/python3.11/site-packages/firebase_admin/_sseclient.py", line 110, in _connect
    self.resp = self.session.get(self.url, stream=True, **self.requests_kwargs)
                ^^^^^^^^^^^^^^^^^^^^^^^^^^^^^^^^^^^^^^^^^^^^^^^^^^^^^^^^^^^^^^^
  File "/home/emanuel/ojos-env/lib/python3.11/site-packages/requests/sessions.py", line 602, in get
    return self.request("GET", url, **kwargs)
           ^^^^^^^^^^^^^^^^^^^^^^^^^^^^^^^^^^
  File "/home/emanuel/ojos-env/lib/python3.11/site-packages/google/auth/transport/requests.py", line 535, in request
    self.credentials.before_request(auth_request, method, url, request_headers)
  File "/home/emanuel/ojos-env/lib/python3.11/site-packages/google/auth/credentials.py", line 239, in before_request
    self._blocking_refresh(request)
  File "/home/emanuel/ojos-env/lib/python3.11/site-packages/google/auth/credentials.py", line 202, in _blocking_refresh
    self.refresh(request)
  File "/home/emanuel/ojos-env/lib/python3.11/site-packages/google/oauth2/service_account.py", line 448, in refresh
    access_token, expiry, _ = _client.jwt_grant(
                              ^^^^^^^^^^^^^^^^^^
  File "/home/emanuel/ojos-env/lib/python3.11/site-packages/google/oauth2/_client.py", line 299, in jwt_grant
    response_data = _token_endpoint_request(
                    ^^^^^^^^^^^^^^^^^^^^^^^^
  File "/home/emanuel/ojos-env/lib/python3.11/site-packages/google/oauth2/_client.py", line 259, in _token_endpoint_request
    response_status_ok, response_data, retryable_error = _token_endpoint_request_no_throw(
                                                         ^^^^^^^^^^^^^^^^^^^^^^^^^^^^^^^^^
  File "/home/emanuel/ojos-env/lib/python3.11/site-packages/google/oauth2/_client.py", line 192, in _token_endpoint_request_no_throw
    response = request(
               ^^^^^^^^
  File "/home/emanuel/ojos-env/lib/python3.11/site-packages/google/auth/transport/requests.py", line 194, in __call__
    raise new_exc from caught_exc
google.auth.exceptions.TransportError: HTTPSConnectionPool(host='oauth2.googleapis.com', port=443): Max retries exceeded with url: /token (Caused by NameResolutionError("<urllib3.connection.HTTPSConnection object at 0x7fff5403a710>: Failed to resolve 'oauth2.googleapis.com' ([Errno -3] Temporary failure in name resolution)"))
/home/emanuel/firebase_mqtt.py:74: DeprecationWarning: Callback API version 1 is deprecated, update to latest version
Exception in thread Thread-1 (start_firebase_watch):
Traceback (most recent call last):
  File "/home/emanuel/ojos-env/lib/python3.11/site-packages/urllib3/connection.py", line 198, in _new_conn
    sock = connection.create_connection(
           ^^^^^^^^^^^^^^^^^^^^^^^^^^^^^
  File "/home/emanuel/ojos-env/lib/python3.11/site-packages/urllib3/util/connection.py", line 60, in create_connection
    for res in socket.getaddrinfo(host, port, family, socket.SOCK_STREAM):
               ^^^^^^^^^^^^^^^^^^^^^^^^^^^^^^^^^^^^^^^^^^^^^^^^^^^^^^^^^^
  File "/usr/lib/python3.11/socket.py", line 962, in getaddrinfo
    for res in _socket.getaddrinfo(host, port, family, type, proto, flags):
               ^^^^^^^^^^^^^^^^^^^^^^^^^^^^^^^^^^^^^^^^^^^^^^^^^^^^^^^^^^^
socket.gaierror: [Errno -3] Temporary failure in name resolution

The above exception was the direct cause of the following exception:

Traceback (most recent call last):
  File "/home/emanuel/ojos-env/lib/python3.11/site-packages/urllib3/connectionpool.py", line 787, in urlopen
    response = self._make_request(
               ^^^^^^^^^^^^^^^^^^^
  File "/home/emanuel/ojos-env/lib/python3.11/site-packages/urllib3/connectionpool.py", line 488, in _make_request
    raise new_e
  File "/home/emanuel/ojos-env/lib/python3.11/site-packages/urllib3/connectionpool.py", line 464, in _make_request
    self._validate_conn(conn)
  File "/home/emanuel/ojos-env/lib/python3.11/site-packages/urllib3/connectionpool.py", line 1093, in _validate_conn
    conn.connect()
  File "/home/emanuel/ojos-env/lib/python3.11/site-packages/urllib3/connection.py", line 753, in connect
    self.sock = sock = self._new_conn()
                       ^^^^^^^^^^^^^^^^
  File "/home/emanuel/ojos-env/lib/python3.11/site-packages/urllib3/connection.py", line 205, in _new_conn
    raise NameResolutionError(self.host, self, e) from e
urllib3.exceptions.NameResolutionError: <urllib3.connection.HTTPSConnection object at 0x7fff3b92a790>: Failed to resolve 'oauth2.googleapis.com' ([Errno -3] Temporary failure in name resolution)

The above exception was the direct cause of the following exception:

Traceback (most recent call last):
  File "/home/emanuel/ojos-env/lib/python3.11/site-packages/requests/adapters.py", line 644, in send
    resp = conn.urlopen(
           ^^^^^^^^^^^^^
  File "/home/emanuel/ojos-env/lib/python3.11/site-packages/urllib3/connectionpool.py", line 871, in urlopen
    return self.urlopen(
           ^^^^^^^^^^^^^
  File "/home/emanuel/ojos-env/lib/python3.11/site-packages/urllib3/connectionpool.py", line 871, in urlopen
    return self.urlopen(
           ^^^^^^^^^^^^^
  File "/home/emanuel/ojos-env/lib/python3.11/site-packages/urllib3/connectionpool.py", line 871, in urlopen
    return self.urlopen(
           ^^^^^^^^^^^^^
  File "/home/emanuel/ojos-env/lib/python3.11/site-packages/urllib3/connectionpool.py", line 841, in urlopen
    retries = retries.increment(
              ^^^^^^^^^^^^^^^^^^
  File "/home/emanuel/ojos-env/lib/python3.11/site-packages/urllib3/util/retry.py", line 519, in increment
    raise MaxRetryError(_pool, url, reason) from reason  # type: ignore[arg-type]
    ^^^^^^^^^^^^^^^^^^^^^^^^^^^^^^^^^^^^^^^^^^^^^^^^^^^
urllib3.exceptions.MaxRetryError: HTTPSConnectionPool(host='oauth2.googleapis.com', port=443): Max retries exceeded with url: /token (Caused by NameResolutionError("<urllib3.connection.HTTPSConnection object at 0x7fff3b92a790>: Failed to resolve 'oauth2.googleapis.com' ([Errno -3] Temporary failure in name resolution)"))

During handling of the above exception, another exception occurred:

Traceback (most recent call last):
  File "/home/emanuel/ojos-env/lib/python3.11/site-packages/google/auth/transport/requests.py", line 187, in __call__
    response = self.session.request(
               ^^^^^^^^^^^^^^^^^^^^^
  File "/home/emanuel/ojos-env/lib/python3.11/site-packages/requests/sessions.py", line 589, in request
    resp = self.send(prep, **send_kwargs)
           ^^^^^^^^^^^^^^^^^^^^^^^^^^^^^^
  File "/home/emanuel/ojos-env/lib/python3.11/site-packages/requests/sessions.py", line 703, in send
    r = adapter.send(request, **kwargs)
        ^^^^^^^^^^^^^^^^^^^^^^^^^^^^^^^
  File "/home/emanuel/ojos-env/lib/python3.11/site-packages/requests/adapters.py", line 677, in send
    raise ConnectionError(e, request=request)
requests.exceptions.ConnectionError: HTTPSConnectionPool(host='oauth2.googleapis.com', port=443): Max retries exceeded with url: /token (Caused by NameResolutionError("<urllib3.connection.HTTPSConnection object at 0x7fff3b92a790>: Failed to resolve 'oauth2.googleapis.com' ([Errno -3] Temporary failure in name resolution)"))

The above exception was the direct cause of the following exception:

Traceback (most recent call last):
  File "/usr/lib/python3.11/threading.py", line 1038, in _bootstrap_inner
    self.run()
  File "/usr/lib/python3.11/threading.py", line 975, in run
    self._target(*self._args, **self._kwargs)
  File "/home/emanuel/firebase_mqtt.py", line 98, in start_firebase_watch
  File "/home/emanuel/ojos-env/lib/python3.11/site-packages/firebase_admin/db.py", line 374, in listen
    return self._listen_with_session(callback)
           ^^^^^^^^^^^^^^^^^^^^^^^^^^^^^^^^^^^
  File "/home/emanuel/ojos-env/lib/python3.11/site-packages/firebase_admin/db.py", line 469, in _listen_with_session
    sse = _sseclient.SSEClient(url, session, **{"params": self._client.params})
          ^^^^^^^^^^^^^^^^^^^^^^^^^^^^^^^^^^^^^^^^^^^^^^^^^^^^^^^^^^^^^^^^^^^^^
  File "/home/emanuel/ojos-env/lib/python3.11/site-packages/firebase_admin/_sseclient.py", line 97, in __init__
    self._connect()
  File "/home/emanuel/ojos-env/lib/python3.11/site-packages/firebase_admin/_sseclient.py", line 110, in _connect
    self.resp = self.session.get(self.url, stream=True, **self.requests_kwargs)
                ^^^^^^^^^^^^^^^^^^^^^^^^^^^^^^^^^^^^^^^^^^^^^^^^^^^^^^^^^^^^^^^
  File "/home/emanuel/ojos-env/lib/python3.11/site-packages/requests/sessions.py", line 602, in get
    return self.request("GET", url, **kwargs)
           ^^^^^^^^^^^^^^^^^^^^^^^^^^^^^^^^^^
  File "/home/emanuel/ojos-env/lib/python3.11/site-packages/google/auth/transport/requests.py", line 535, in request
    self.credentials.before_request(auth_request, method, url, request_headers)
  File "/home/emanuel/ojos-env/lib/python3.11/site-packages/google/auth/credentials.py", line 239, in before_request
    self._blocking_refresh(request)
  File "/home/emanuel/ojos-env/lib/python3.11/site-packages/google/auth/credentials.py", line 202, in _blocking_refresh
    self.refresh(request)
  File "/home/emanuel/ojos-env/lib/python3.11/site-packages/google/oauth2/service_account.py", line 448, in refresh
    access_token, expiry, _ = _client.jwt_grant(
                              ^^^^^^^^^^^^^^^^^^
  File "/home/emanuel/ojos-env/lib/python3.11/site-packages/google/oauth2/_client.py", line 299, in jwt_grant
    response_data = _token_endpoint_request(
                    ^^^^^^^^^^^^^^^^^^^^^^^^
  File "/home/emanuel/ojos-env/lib/python3.11/site-packages/google/oauth2/_client.py", line 259, in _token_endpoint_request
    response_status_ok, response_data, retryable_error = _token_endpoint_request_no_throw(
                                                         ^^^^^^^^^^^^^^^^^^^^^^^^^^^^^^^^^
  File "/home/emanuel/ojos-env/lib/python3.11/site-packages/google/oauth2/_client.py", line 192, in _token_endpoint_request_no_throw
    response = request(
               ^^^^^^^^
  File "/home/emanuel/ojos-env/lib/python3.11/site-packages/google/auth/transport/requests.py", line 194, in __call__
    raise new_exc from caught_exc
google.auth.exceptions.TransportError: HTTPSConnectionPool(host='oauth2.googleapis.com', port=443): Max retries exceeded with url: /token (Caused by NameResolutionError("<urllib3.connection.HTTPSConnection object at 0x7fff3b92a790>: Failed to resolve 'oauth2.googleapis.com' ([Errno -3] Temporary failure in name resolution)"))
/home/emanuel/firebase_mqtt.py:74: DeprecationWarning: Callback API version 1 is deprecated, update to latest version
Exception in thread Thread-1 (start_firebase_watch):
Traceback (most recent call last):
  File "/home/emanuel/ojos-env/lib/python3.11/site-packages/urllib3/connection.py", line 198, in _new_conn
    sock = connection.create_connection(
           ^^^^^^^^^^^^^^^^^^^^^^^^^^^^^
  File "/home/emanuel/ojos-env/lib/python3.11/site-packages/urllib3/util/connection.py", line 60, in create_connection
    for res in socket.getaddrinfo(host, port, family, socket.SOCK_STREAM):
               ^^^^^^^^^^^^^^^^^^^^^^^^^^^^^^^^^^^^^^^^^^^^^^^^^^^^^^^^^^
  File "/usr/lib/python3.11/socket.py", line 962, in getaddrinfo
    for res in _socket.getaddrinfo(host, port, family, type, proto, flags):
               ^^^^^^^^^^^^^^^^^^^^^^^^^^^^^^^^^^^^^^^^^^^^^^^^^^^^^^^^^^^
socket.gaierror: [Errno -3] Temporary failure in name resolution

The above exception was the direct cause of the following exception:

Traceback (most recent call last):
  File "/home/emanuel/ojos-env/lib/python3.11/site-packages/urllib3/connectionpool.py", line 787, in urlopen
    response = self._make_request(
               ^^^^^^^^^^^^^^^^^^^
  File "/home/emanuel/ojos-env/lib/python3.11/site-packages/urllib3/connectionpool.py", line 488, in _make_request
    raise new_e
  File "/home/emanuel/ojos-env/lib/python3.11/site-packages/urllib3/connectionpool.py", line 464, in _make_request
    self._validate_conn(conn)
  File "/home/emanuel/ojos-env/lib/python3.11/site-packages/urllib3/connectionpool.py", line 1093, in _validate_conn
    conn.connect()
  File "/home/emanuel/ojos-env/lib/python3.11/site-packages/urllib3/connection.py", line 753, in connect
    self.sock = sock = self._new_conn()
                       ^^^^^^^^^^^^^^^^
  File "/home/emanuel/ojos-env/lib/python3.11/site-packages/urllib3/connection.py", line 205, in _new_conn
    raise NameResolutionError(self.host, self, e) from e
urllib3.exceptions.NameResolutionError: <urllib3.connection.HTTPSConnection object at 0x7fff4e96a650>: Failed to resolve 'oauth2.googleapis.com' ([Errno -3] Temporary failure in name resolution)

The above exception was the direct cause of the following exception:

Traceback (most recent call last):
  File "/home/emanuel/ojos-env/lib/python3.11/site-packages/requests/adapters.py", line 644, in send
    resp = conn.urlopen(
           ^^^^^^^^^^^^^
  File "/home/emanuel/ojos-env/lib/python3.11/site-packages/urllib3/connectionpool.py", line 871, in urlopen
    return self.urlopen(
           ^^^^^^^^^^^^^
  File "/home/emanuel/ojos-env/lib/python3.11/site-packages/urllib3/connectionpool.py", line 871, in urlopen
    return self.urlopen(
           ^^^^^^^^^^^^^
  File "/home/emanuel/ojos-env/lib/python3.11/site-packages/urllib3/connectionpool.py", line 871, in urlopen
    return self.urlopen(
           ^^^^^^^^^^^^^
  File "/home/emanuel/ojos-env/lib/python3.11/site-packages/urllib3/connectionpool.py", line 841, in urlopen
    retries = retries.increment(
              ^^^^^^^^^^^^^^^^^^
  File "/home/emanuel/ojos-env/lib/python3.11/site-packages/urllib3/util/retry.py", line 519, in increment
    raise MaxRetryError(_pool, url, reason) from reason  # type: ignore[arg-type]
    ^^^^^^^^^^^^^^^^^^^^^^^^^^^^^^^^^^^^^^^^^^^^^^^^^^^
urllib3.exceptions.MaxRetryError: HTTPSConnectionPool(host='oauth2.googleapis.com', port=443): Max retries exceeded with url: /token (Caused by NameResolutionError("<urllib3.connection.HTTPSConnection object at 0x7fff4e96a650>: Failed to resolve 'oauth2.googleapis.com' ([Errno -3] Temporary failure in name resolution)"))

During handling of the above exception, another exception occurred:

Traceback (most recent call last):
  File "/home/emanuel/ojos-env/lib/python3.11/site-packages/google/auth/transport/requests.py", line 187, in __call__
    response = self.session.request(
               ^^^^^^^^^^^^^^^^^^^^^
  File "/home/emanuel/ojos-env/lib/python3.11/site-packages/requests/sessions.py", line 589, in request
    resp = self.send(prep, **send_kwargs)
           ^^^^^^^^^^^^^^^^^^^^^^^^^^^^^^
  File "/home/emanuel/ojos-env/lib/python3.11/site-packages/requests/sessions.py", line 703, in send
    r = adapter.send(request, **kwargs)
        ^^^^^^^^^^^^^^^^^^^^^^^^^^^^^^^
  File "/home/emanuel/ojos-env/lib/python3.11/site-packages/requests/adapters.py", line 677, in send
    raise ConnectionError(e, request=request)
requests.exceptions.ConnectionError: HTTPSConnectionPool(host='oauth2.googleapis.com', port=443): Max retries exceeded with url: /token (Caused by NameResolutionError("<urllib3.connection.HTTPSConnection object at 0x7fff4e96a650>: Failed to resolve 'oauth2.googleapis.com' ([Errno -3] Temporary failure in name resolution)"))

The above exception was the direct cause of the following exception:

Traceback (most recent call last):
  File "/usr/lib/python3.11/threading.py", line 1038, in _bootstrap_inner
    self.run()
  File "/usr/lib/python3.11/threading.py", line 975, in run
    self._target(*self._args, **self._kwargs)
  File "/home/emanuel/firebase_mqtt.py", line 98, in start_firebase_watch
  File "/home/emanuel/ojos-env/lib/python3.11/site-packages/firebase_admin/db.py", line 374, in listen
    return self._listen_with_session(callback)
           ^^^^^^^^^^^^^^^^^^^^^^^^^^^^^^^^^^^
  File "/home/emanuel/ojos-env/lib/python3.11/site-packages/firebase_admin/db.py", line 469, in _listen_with_session
    sse = _sseclient.SSEClient(url, session, **{"params": self._client.params})
          ^^^^^^^^^^^^^^^^^^^^^^^^^^^^^^^^^^^^^^^^^^^^^^^^^^^^^^^^^^^^^^^^^^^^^
  File "/home/emanuel/ojos-env/lib/python3.11/site-packages/firebase_admin/_sseclient.py", line 97, in __init__
    self._connect()
  File "/home/emanuel/ojos-env/lib/python3.11/site-packages/firebase_admin/_sseclient.py", line 110, in _connect
    self.resp = self.session.get(self.url, stream=True, **self.requests_kwargs)
                ^^^^^^^^^^^^^^^^^^^^^^^^^^^^^^^^^^^^^^^^^^^^^^^^^^^^^^^^^^^^^^^
  File "/home/emanuel/ojos-env/lib/python3.11/site-packages/requests/sessions.py", line 602, in get
    return self.request("GET", url, **kwargs)
           ^^^^^^^^^^^^^^^^^^^^^^^^^^^^^^^^^^
  File "/home/emanuel/ojos-env/lib/python3.11/site-packages/google/auth/transport/requests.py", line 535, in request
    self.credentials.before_request(auth_request, method, url, request_headers)
  File "/home/emanuel/ojos-env/lib/python3.11/site-packages/google/auth/credentials.py", line 239, in before_request
    self._blocking_refresh(request)
  File "/home/emanuel/ojos-env/lib/python3.11/site-packages/google/auth/credentials.py", line 202, in _blocking_refresh
    self.refresh(request)
  File "/home/emanuel/ojos-env/lib/python3.11/site-packages/google/oauth2/service_account.py", line 448, in refresh
    access_token, expiry, _ = _client.jwt_grant(
                              ^^^^^^^^^^^^^^^^^^
  File "/home/emanuel/ojos-env/lib/python3.11/site-packages/google/oauth2/_client.py", line 299, in jwt_grant
    response_data = _token_endpoint_request(
                    ^^^^^^^^^^^^^^^^^^^^^^^^
  File "/home/emanuel/ojos-env/lib/python3.11/site-packages/google/oauth2/_client.py", line 259, in _token_endpoint_request
    response_status_ok, response_data, retryable_error = _token_endpoint_request_no_throw(
                                                         ^^^^^^^^^^^^^^^^^^^^^^^^^^^^^^^^^
  File "/home/emanuel/ojos-env/lib/python3.11/site-packages/google/oauth2/_client.py", line 192, in _token_endpoint_request_no_throw
    response = request(
               ^^^^^^^^
  File "/home/emanuel/ojos-env/lib/python3.11/site-packages/google/auth/transport/requests.py", line 194, in __call__
    raise new_exc from caught_exc
google.auth.exceptions.TransportError: HTTPSConnectionPool(host='oauth2.googleapis.com', port=443): Max retries exceeded with url: /token (Caused by NameResolutionError("<urllib3.connection.HTTPSConnection object at 0x7fff4e96a650>: Failed to resolve 'oauth2.googleapis.com' ([Errno -3] Temporary failure in name resolution)"))
